2022-05-18 01:15:32 +0000 - dagster - DEBUG - download_csv_dataset - 3bde4204-420f-4af7-a4ee-8e71c0f278d9 - 486 - a - LOGS_CAPTURED - Started capturing logs for step: a.
2022-05-18 01:15:33 +0000 - dagster - DEBUG - download_csv_dataset - 3bde4204-420f-4af7-a4ee-8e71c0f278d9 - 486 - a - STEP_START - Started execution of step "a".
2022-05-18 01:15:35 +0000 - dagster - ERROR - download_csv_dataset - 3bde4204-420f-4af7-a4ee-8e71c0f278d9 - 486 - a - STEP_FAILURE - Execution of step "a" failed.

dagster.core.errors.DagsterExecutionStepExecutionError: Error occurred while executing solid "a"::

FileNotFoundError: [Errno 2] No such file or directory: '/usr/src/app/./jobs/shell_scripts/download_csv_file.sh'

Stack Trace:
  File "/usr/local/lib/python3.10/site-packages/dagster/core/execution/plan/utils.py", line 47, in solid_execution_error_boundary
    yield
  File "/usr/local/lib/python3.10/site-packages/dagster/utils/__init__.py", line 398, in iterate_with_context
    next_output = next(iterator)
  File "/usr/local/lib/python3.10/site-packages/dagster/core/execution/plan/compute_generator.py", line 65, in _coerce_solid_compute_fn_to_iterator
    result = fn(context, **kwargs) if context_arg_provided else fn(**kwargs)
  File "/usr/local/lib/python3.10/site-packages/dagster_shell/solids.py", line 333, in _shell_script_fn
    output, return_code = execute_script_file(
  File "/usr/local/lib/python3.10/site-packages/dagster_shell/utils.py", line 70, in execute_script_file
    with open(shell_script_path, "rb") as f:

